Traceback (most recent call last):
  File "/Users/jfoley19/miniforge3/envs/jbook/lib/python3.12/site-packages/jupyter_cache/executors/utils.py", line 58, in single_nb_execution
    executenb(
  File "/Users/jfoley19/miniforge3/envs/jbook/lib/python3.12/site-packages/nbclient/client.py", line 1319, in execute
    return NotebookClient(nb=nb, resources=resources, km=km, **kwargs).execute()
           ^^^^^^^^^^^^^^^^^^^^^^^^^^^^^^^^^^^^^^^^^^^^^^^^^^^^^^^^^^^^^^^^^^^^^
  File "/Users/jfoley19/miniforge3/envs/jbook/lib/python3.12/site-packages/jupyter_core/utils/__init__.py", line 165, in wrapped
    return loop.run_until_complete(inner)
           ^^^^^^^^^^^^^^^^^^^^^^^^^^^^^^
  File "/Users/jfoley19/miniforge3/envs/jbook/lib/python3.12/asyncio/base_events.py", line 691, in run_until_complete
    return future.result()
           ^^^^^^^^^^^^^^^
  File "/Users/jfoley19/miniforge3/envs/jbook/lib/python3.12/site-packages/nbclient/client.py", line 709, in async_execute
    await self.async_execute_cell(
  File "/Users/jfoley19/miniforge3/envs/jbook/lib/python3.12/site-packages/nbclient/client.py", line 1062, in async_execute_cell
    await self._check_raise_for_error(cell, cell_index, exec_reply)
  File "/Users/jfoley19/miniforge3/envs/jbook/lib/python3.12/site-packages/nbclient/client.py", line 918, in _check_raise_for_error
    raise CellExecutionError.from_cell_and_msg(cell, exec_reply_content)
nbclient.exceptions.CellExecutionError: An error occurred while executing the following cell:
------------------
# TODO: Assign ket_alpha as a column vector using np.array
# Example: np.array([[...], [...]])
ket_alpha = ...

# TODO: Assign ket_beta as a column vector using np.array
ket_beta = ...

# Print both kets (already provided for you)
print("|alpha>")
print(ket_alpha)
print(ket_alpha.shape)

print("|beta>")
print(ket_beta)
------------------

----- stdout -----
|alpha>
Ellipsis
------------------

[31m---------------------------------------------------------------------------[39m
[31mAttributeError[39m                            Traceback (most recent call last)
[36mCell[39m[36m [39m[32mIn[3][39m[32m, line 11[39m
[32m      9[39m [38;5;28mprint[39m([33m"[39m[33m|alpha>[39m[33m"[39m)
[32m     10[39m [38;5;28mprint[39m(ket_alpha)
[32m---> [39m[32m11[39m [38;5;28mprint[39m([43mket_alpha[49m[43m.[49m[43mshape[49m)
[32m     13[39m [38;5;28mprint[39m([33m"[39m[33m|beta>[39m[33m"[39m)
[32m     14[39m [38;5;28mprint[39m(ket_beta)

[31mAttributeError[39m: 'ellipsis' object has no attribute 'shape'

